<?xml version='1.0' encoding='utf-8'?>
<robot name="box1">

    <link name="link0">
      <inertial>
        <origin xyz="0 0 0" rpy="0 0 0" />
        <mass value="0.001" />
        <inertia ixx="0.01" iyy="0.01" izz="0.01" ixy="0" ixz="0" iyz="0" />
      </inertial>
    </link>
    <link name="link1">
      <inertial>
        <origin xyz="0 0 0" rpy="0 0 0" />
        <mass value="1e-10" />
        <inertia ixx="1e-10" iyy="1e-10" izz="1e-10" ixy="0" ixz="0" iyz="0" />
      </inertial>
    </link>
    <link name="link2">
      <inertial>
        <origin xyz="0 0 0" rpy="0 0 0" />
        <mass value="1e-10" />
        <inertia ixx="1e-10" iyy="1e-10" izz="1e-10" ixy="0" ixz="0" iyz="0" />
      </inertial>
    </link>
    <link name="link3">
      <inertial>
        <origin xyz="0 0 0" rpy="0 0 0" />
        <mass value="1e-10" />
        <inertia ixx="1e-10" iyy="1e-10" izz="1e-10" ixy="0" ixz="0" iyz="0" />
      </inertial>
    </link>
      <link name="link4">
      <inertial>
        <origin xyz="0 0 0" rpy="0 0 0" />
        <mass value="1e-10" />
        <inertia ixx="1e-10" iyy="1e-10" izz="1e-10" ixy="0" ixz="0" iyz="0" />
      </inertial>
    </link>
    <link name="link5">
      <inertial>
        <origin xyz="0 0 0" rpy="0 0 0" />
        <mass value="1e-10" />
        <inertia ixx="1e-10" iyy="1e-10" izz="1e-10" ixy="0" ixz="0" iyz="0" />
      </inertial>
    </link>
    <link name="link6">
      <inertial>
        <origin xyz="1.32 0.06 0" rpy="0 0 0" />
        <mass value="0.1" />
        <inertia ixx="1e-2" iyy="1e-2" izz="1e-2" ixy="0" ixz="0" iyz="0" />
      </inertial>
      <visual>
        <origin xyz="1.45 0 0" rpy="0 1.57 0" />
        <geometry>
          <mesh filename="../../../model/project_models/package.obj" scale="0.02 0.1 0.14"/>
        </geometry>
      </visual> 
      <collision>
        <origin xyz="1.4 .06 .00" rpy="0 0 0" />
        <geometry>
          <box size="0.2 0.13 0.03"/>
        </geometry>
      </collision> 

      <!-- visualize center of mass
      <visual>
        <origin xyz="1.32 0.06 0" rpy="0 0 0" />
            <geometry>
                <sphere radius="0.01" />
            </geometry>
            <material name="material_red">
                <color rgba="0.5 0.0 0.0 1.0" />
            </material>
      </visual>
      -->

        <!-- visualize collision mesh
      <visual>
        <origin xyz="1.4 .06 .006" rpy="0 0 0" />
        <geometry>
          <box size="0.2 0.13 0.011"/>
        </geometry>
      <material name="material_blue">
        <color rgba="0.3 0.3 0.9 1.0" />
      </material>
      </visual> 
        -->
    </link>
    
    <joint name="joint1" type="prismatic">
      <origin xyz="0 0 0" rpy="0 0 0"/>
      <parent link="link0"/>
      <child link="link1"/>
      <axis xyz="0 0 1"/>
      <limit effort="21.3" lower="-100" upper="100" velocity="21.3"/>
    </joint>
    <joint name="joint2" type="prismatic">
      <origin xyz="0 0 0" rpy="0 0 0"/>
      <parent link="link1"/>
      <child link="link2"/>
      <axis xyz="0 1 0"/>
      <limit effort="21.3" lower="-100" upper="100" velocity="21.3"/>
    </joint>
    <joint name="joint3" type="prismatic">
      <origin xyz="0 0 0" rpy="0 0 0"/>
      <parent link="link2"/>
      <child link="link3"/>
      <axis xyz="1 0 0"/>
      <limit effort="21.3" lower="-100" upper="100" velocity="21.3"/>
    </joint>
    <joint name="joint4" type="revolute">
      <origin xyz="0 0 0" rpy="0 0 0"/>
      <parent link="link3"/>
      <child link="link4"/>
        <axis xyz="1 0 0"/>
      <limit effort="21.3" lower="0" upper="6.28" velocity="21.3"/>
    </joint>
    <joint name="joint5" type="revolute">
      <origin xyz="0 0 0" rpy="0 0 0"/>
      <parent link="link4"/>
      <child link="link5"/>
        <axis xyz="0 1 0"/>
      <limit effort="21.3" lower="0" upper="6.28" velocity="21.3"/>
    </joint>
    <joint name="joint6" type="revolute">
      <origin xyz="0 0 0" rpy="0 0 0"/>
      <parent link="link5"/>
      <child link="link6"/>
        <axis xyz="0 0 1"/>
      <limit effort="21.3" lower="0" upper="6.28" velocity="21.3"/>
    </joint>
<!--     <joint name="joint4" type="spherical">
      <origin xyz="0 0 0" rpy="0 0 0"/>
      <parent link="link3"/>
      <child link="link4"/>
      <limit effort="100" lower="-100" upper="100" velocity="100"/>
    </joint> -->
</robot>

</xml>
