<?xml version='1.0' encoding='utf-8'?>
<robot name="mailbox">

    <link name="link0">
      <inertial>
        <origin xyz="0 0 0" rpy="0 0 0" />
        <mass value="0.001" />
        <inertia ixx="0.01" iyy="0.01" izz="0.01" ixy="0" ixz="0" iyz="0" />
      </inertial>
      <visual>
        <origin xyz="0 0 0" rpy="0 0 0" />
            <geometry>
                <sphere radius="0.01" />
            </geometry>
            <material name="material_red">
                <color rgba="0.5 0.0 0.0 1.0" />
            </material>
      </visual>
        <visual>
            <origin xyz="0 0 0" rpy="0 0 0" />
            <geometry>
                <mesh filename="../../../model/project_models/mailbox_new.obj" scale="0.52 0.52 0.52"/>
            </geometry>
            <material name="material_red">
                <texture filename="../../../model/project_models/mailbox_new.mtl" />
            </material>
        </visual>

    </link>

    <link name="link1">
      <inertial>
        <origin xyz="0 0.21 0" rpy="0 0 0" />
        <mass value="0.1" />
        <inertia ixx="1e-3" iyy="1e-3" izz="1e-3" ixy="0" ixz="0" iyz="0" />
      </inertial>
      <visual>
        <origin xyz="0 0 0" rpy="0 0 0" />
            <geometry>
                <sphere radius="0.05" />
            </geometry>
            <material name="material_red">
                <color rgba="0.5 0.0 0.0 1.0" />
            </material>
      </visual>
      <visual>
        <origin xyz="0 0 -0.13" rpy="0 0 0" />
        <geometry>
          <mesh filename="../../../model/project_models/mailboxlid.obj" scale="0.52 0.52 0.52"/>
        </geometry>
      </visual>
      <visual>
        <origin xyz="0 0.21 0" rpy="0 0 0" />
        <geometry>
          <box size="0.1 0.05 0.05" />
        </geometry>
      </visual>
      <collision>
        <origin xyz="0 0.21 0" rpy="0 0 0" />
        <geometry>
          <box size="0.1 0.05 0.05" />
        </geometry>
      </collision>
      <!-- <visual>
        <origin xyz="0 0.5 0" rpy="0 0 0" />
        <geometry>
          <box size="0.02 0.43 0.1" />
        </geometry>
      </visual> -->
    </link>

        <!-- visualize collision mesh
      <visual>
        <origin xyz="1.4 .06 .006" rpy="0 0 0" />
        <geometry>
          <box size="0.2 0.13 0.011"/>
        </geometry>
      <material name="material_blue">
        <color rgba="0.3 0.3 0.9 1.0" />
      </material>
      </visual> 
      <origin xyz="6 1 -0.3" rpy="0 0 0" />
        -->
    
    <joint name="joint1" type="revolute">
      <origin xyz="0.575 1.84 .13" rpy="0 0 0" />
      <parent link="link0"/>
      <child link="link1"/>
        <axis xyz="0 0 1"/>
      <limit effort="21.3" lower="-1.57" upper="0" velocity="21.3"/>
    </joint>
</robot>

</xml>
